[2025-03-27T14:43:28.095-0500] {local_task_job_runner.py:123} INFO - ::group::Pre task execution logs
[2025-03-27T14:43:28.102-0500] {taskinstance.py:2614} INFO - Dependencies all met for dep_context=non-requeueable deps ti=<TaskInstance: example_branch_operator.branching_venv manual__2025-03-27T19:43:04.855946+00:00 [queued]>
[2025-03-27T14:43:28.106-0500] {taskinstance.py:2614} INFO - Dependencies all met for dep_context=requeueable deps ti=<TaskInstance: example_branch_operator.branching_venv manual__2025-03-27T19:43:04.855946+00:00 [queued]>
[2025-03-27T14:43:28.106-0500] {taskinstance.py:2867} INFO - Starting attempt 1 of 1
[2025-03-27T14:43:28.523-0500] {taskinstance.py:2890} INFO - Executing <Task(BranchPythonVirtualenvOperator): branching_venv> on 2025-03-27 19:43:04.855946+00:00
[2025-03-27T14:43:28.525-0500] {standard_task_runner.py:72} INFO - Started process 1773877 to run task
[2025-03-27T14:43:28.527-0500] {standard_task_runner.py:104} INFO - Running: ['airflow', 'tasks', 'run', 'example_branch_operator', 'branching_venv', 'manual__2025-03-27T19:43:04.855946+00:00', '--job-id', '12', '--raw', '--subdir', '/home/udhbhav/miniconda3/lib/python3.11/site-packages/airflow/example_dags/example_branch_operator.py', '--cfg-path', '/tmp/tmpvdolql3d']
[2025-03-27T14:43:28.527-0500] {standard_task_runner.py:105} INFO - Job 12: Subtask branching_venv
[2025-03-27T14:43:29.062-0500] {task_command.py:467} INFO - Running <TaskInstance: example_branch_operator.branching_venv manual__2025-03-27T19:43:04.855946+00:00 [running]> on host royal-07.cs.wisc.edu
[2025-03-27T14:43:29.330-0500] {taskinstance.py:3134} INFO - Exporting env vars: AIRFLOW_CTX_DAG_OWNER='airflow' AIRFLOW_CTX_DAG_ID='example_branch_operator' AIRFLOW_CTX_TASK_ID='branching_venv' AIRFLOW_CTX_EXECUTION_DATE='2025-03-27T19:43:04.855946+00:00' AIRFLOW_CTX_TRY_NUMBER='1' AIRFLOW_CTX_DAG_RUN_ID='manual__2025-03-27T19:43:04.855946+00:00'
[2025-03-27T14:43:29.330-0500] {logging_mixin.py:190} INFO - Task instance is in running state
[2025-03-27T14:43:29.330-0500] {logging_mixin.py:190} INFO -  Previous state of the Task instance: queued
[2025-03-27T14:43:29.331-0500] {logging_mixin.py:190} INFO - Current task name:branching_venv state:running start_date:2025-03-27 19:43:28.102641+00:00
[2025-03-27T14:43:29.331-0500] {logging_mixin.py:190} INFO - Dag name:example_branch_operator and current dag run status:running
[2025-03-27T14:43:29.331-0500] {taskinstance.py:732} INFO - ::endgroup::
[2025-03-27T14:43:29.331-0500] {baseoperator.py:423} WARNING - BranchPythonVirtualenvOperator.execute cannot be called outside TaskInstance!
[2025-03-27T14:43:29.331-0500] {baseoperator.py:423} WARNING - BranchPythonVirtualenvOperator.execute cannot be called outside TaskInstance!
[2025-03-27T14:43:29.333-0500] {python.py:809} INFO - Python virtual environment will be cached in /tmp/venv-5ea997a7
[2025-03-27T14:43:29.334-0500] {process_utils.py:186} INFO - Executing cmd: /home/udhbhav/miniconda3/bin/python -m virtualenv /tmp/venv-5ea997a7 --system-site-packages --python=python
[2025-03-27T14:43:29.334-0500] {process_utils.py:190} INFO - Output:
[2025-03-27T14:43:29.342-0500] {process_utils.py:194} INFO - /home/udhbhav/miniconda3/bin/python: No module named virtualenv
[2025-03-27T14:43:29.346-0500] {taskinstance.py:3313} ERROR - Task failed with exception
Traceback (most recent call last):
  File "/home/udhbhav/miniconda3/lib/python3.11/site-packages/airflow/operators/python.py", line 852, in _ensure_venv_cache_exists
    self._prepare_venv(venv_path)
  File "/home/udhbhav/miniconda3/lib/python3.11/site-packages/airflow/operators/python.py", line 769, in _prepare_venv
    prepare_virtualenv(
  File "/home/udhbhav/miniconda3/lib/python3.11/site-packages/airflow/utils/python_virtualenv.py", line 105, in prepare_virtualenv
    execute_in_subprocess(virtualenv_cmd)
  File "/home/udhbhav/miniconda3/lib/python3.11/site-packages/airflow/utils/process_utils.py", line 175, in execute_in_subprocess
    execute_in_subprocess_with_kwargs(cmd, cwd=cwd, env=env)
  File "/home/udhbhav/miniconda3/lib/python3.11/site-packages/airflow/utils/process_utils.py", line 198, in execute_in_subprocess_with_kwargs
    raise subprocess.CalledProcessError(exit_code, cmd)
subprocess.CalledProcessError: Command '['/home/udhbhav/miniconda3/bin/python', '-m', 'virtualenv', '/tmp/venv-5ea997a7', '--system-site-packages', '--python=python']' returned non-zero exit status 1.

The above exception was the direct cause of the following exception:

Traceback (most recent call last):
  File "/home/udhbhav/miniconda3/lib/python3.11/site-packages/airflow/models/taskinstance.py", line 768, in _execute_task
    result = _execute_callable(context=context, **execute_callable_kwargs)
             ^^^^^^^^^^^^^^^^^^^^^^^^^^^^^^^^^^^^^^^^^^^^^^^^^^^^^^^^^^^^^
  File "/home/udhbhav/miniconda3/lib/python3.11/site-packages/airflow/models/taskinstance.py", line 734, in _execute_callable
    return ExecutionCallableRunner(
           ^^^^^^^^^^^^^^^^^^^^^^^^
  File "/home/udhbhav/miniconda3/lib/python3.11/site-packages/airflow/utils/operator_helpers.py", line 252, in run
    return self.func(*args, **kwargs)
           ^^^^^^^^^^^^^^^^^^^^^^^^^^
  File "/home/udhbhav/miniconda3/lib/python3.11/site-packages/airflow/models/baseoperator.py", line 424, in wrapper
    return func(self, *args, **kwargs)
           ^^^^^^^^^^^^^^^^^^^^^^^^^^^
  File "/home/udhbhav/miniconda3/lib/python3.11/site-packages/airflow/operators/python.py", line 901, in execute
    return self.do_branch(context, super().execute(context))
                                   ^^^^^^^^^^^^^^^^^^^^^^^^
  File "/home/udhbhav/miniconda3/lib/python3.11/site-packages/airflow/models/baseoperator.py", line 424, in wrapper
    return func(self, *args, **kwargs)
           ^^^^^^^^^^^^^^^^^^^^^^^^^^^
  File "/home/udhbhav/miniconda3/lib/python3.11/site-packages/airflow/operators/python.py", line 505, in execute
    return super().execute(context=serializable_context)
           ^^^^^^^^^^^^^^^^^^^^^^^^^^^^^^^^^^^^^^^^^^^^^
  File "/home/udhbhav/miniconda3/lib/python3.11/site-packages/airflow/models/baseoperator.py", line 424, in wrapper
    return func(self, *args, **kwargs)
           ^^^^^^^^^^^^^^^^^^^^^^^^^^^
  File "/home/udhbhav/miniconda3/lib/python3.11/site-packages/airflow/operators/python.py", line 238, in execute
    return_value = self.execute_callable()
                   ^^^^^^^^^^^^^^^^^^^^^^^
  File "/home/udhbhav/miniconda3/lib/python3.11/site-packages/airflow/operators/python.py", line 862, in execute_callable
    venv_path = self._ensure_venv_cache_exists(Path(self.venv_cache_path))
                ^^^^^^^^^^^^^^^^^^^^^^^^^^^^^^^^^^^^^^^^^^^^^^^^^^^^^^^^^^
  File "/home/udhbhav/miniconda3/lib/python3.11/site-packages/airflow/operators/python.py", line 856, in _ensure_venv_cache_exists
    raise AirflowException(f"Unable to create new virtual environment in {venv_path}") from e
airflow.exceptions.AirflowException: Unable to create new virtual environment in /tmp/venv-5ea997a7
[2025-03-27T14:43:29.349-0500] {logging_mixin.py:190} INFO - Task instance in failure state
[2025-03-27T14:43:29.349-0500] {logging_mixin.py:190} INFO - Task start:2025-03-27 19:43:28.102641+00:00 end:2025-03-27 19:43:29.349162+00:00 duration:1.246521
[2025-03-27T14:43:29.349-0500] {logging_mixin.py:190} INFO - Task:<Task(BranchPythonVirtualenvOperator): branching_venv> dag:<DAG: example_branch_operator> dagrun:<DagRun example_branch_operator @ 2025-03-27 19:43:04.855946+00:00: manual__2025-03-27T19:43:04.855946+00:00, state:running, queued_at: 2025-03-27 19:43:04.864618+00:00. externally triggered: True>
[2025-03-27T14:43:29.349-0500] {logging_mixin.py:190} INFO - Failure caused by Unable to create new virtual environment in /tmp/venv-5ea997a7
[2025-03-27T14:43:29.350-0500] {taskinstance.py:1226} INFO - Marking task as FAILED. dag_id=example_branch_operator, task_id=branching_venv, run_id=manual__2025-03-27T19:43:04.855946+00:00, execution_date=20250327T194304, start_date=20250327T194328, end_date=20250327T194329
[2025-03-27T14:43:29.617-0500] {taskinstance.py:341} INFO - ::group::Post task execution logs
[2025-03-27T14:43:29.617-0500] {standard_task_runner.py:124} ERROR - Failed to execute job 12 for task branching_venv (Unable to create new virtual environment in /tmp/venv-5ea997a7; 1773877)
Traceback (most recent call last):
  File "/home/udhbhav/miniconda3/lib/python3.11/site-packages/airflow/operators/python.py", line 852, in _ensure_venv_cache_exists
    self._prepare_venv(venv_path)
  File "/home/udhbhav/miniconda3/lib/python3.11/site-packages/airflow/operators/python.py", line 769, in _prepare_venv
    prepare_virtualenv(
  File "/home/udhbhav/miniconda3/lib/python3.11/site-packages/airflow/utils/python_virtualenv.py", line 105, in prepare_virtualenv
    execute_in_subprocess(virtualenv_cmd)
  File "/home/udhbhav/miniconda3/lib/python3.11/site-packages/airflow/utils/process_utils.py", line 175, in execute_in_subprocess
    execute_in_subprocess_with_kwargs(cmd, cwd=cwd, env=env)
  File "/home/udhbhav/miniconda3/lib/python3.11/site-packages/airflow/utils/process_utils.py", line 198, in execute_in_subprocess_with_kwargs
    raise subprocess.CalledProcessError(exit_code, cmd)
subprocess.CalledProcessError: Command '['/home/udhbhav/miniconda3/bin/python', '-m', 'virtualenv', '/tmp/venv-5ea997a7', '--system-site-packages', '--python=python']' returned non-zero exit status 1.

The above exception was the direct cause of the following exception:

Traceback (most recent call last):
  File "/home/udhbhav/miniconda3/lib/python3.11/site-packages/airflow/task/task_runner/standard_task_runner.py", line 117, in _start_by_fork
    ret = args.func(args, dag=self.dag)
          ^^^^^^^^^^^^^^^^^^^^^^^^^^^^^
  File "/home/udhbhav/miniconda3/lib/python3.11/site-packages/airflow/cli/cli_config.py", line 49, in command
    return func(*args, **kwargs)
           ^^^^^^^^^^^^^^^^^^^^^
  File "/home/udhbhav/miniconda3/lib/python3.11/site-packages/airflow/utils/cli.py", line 116, in wrapper
    return f(*args, **kwargs)
           ^^^^^^^^^^^^^^^^^^
  File "/home/udhbhav/miniconda3/lib/python3.11/site-packages/airflow/cli/commands/task_command.py", line 483, in task_run
    task_return_code = _run_task_by_selected_method(args, _dag, ti)
                       ^^^^^^^^^^^^^^^^^^^^^^^^^^^^^^^^^^^^^^^^^^^^
  File "/home/udhbhav/miniconda3/lib/python3.11/site-packages/airflow/cli/commands/task_command.py", line 256, in _run_task_by_selected_method
    return _run_raw_task(args, ti)
           ^^^^^^^^^^^^^^^^^^^^^^^
  File "/home/udhbhav/miniconda3/lib/python3.11/site-packages/airflow/cli/commands/task_command.py", line 341, in _run_raw_task
    return ti._run_raw_task(
           ^^^^^^^^^^^^^^^^^
  File "/home/udhbhav/miniconda3/lib/python3.11/site-packages/airflow/utils/session.py", line 97, in wrapper
    return func(*args, session=session, **kwargs)
           ^^^^^^^^^^^^^^^^^^^^^^^^^^^^^^^^^^^^^^
  File "/home/udhbhav/miniconda3/lib/python3.11/site-packages/airflow/models/taskinstance.py", line 3006, in _run_raw_task
    return _run_raw_task(
           ^^^^^^^^^^^^^^
  File "/home/udhbhav/miniconda3/lib/python3.11/site-packages/airflow/models/taskinstance.py", line 274, in _run_raw_task
    TaskInstance._execute_task_with_callbacks(
  File "/home/udhbhav/miniconda3/lib/python3.11/site-packages/airflow/models/taskinstance.py", line 3161, in _execute_task_with_callbacks
    result = self._execute_task(context, task_orig)
             ^^^^^^^^^^^^^^^^^^^^^^^^^^^^^^^^^^^^^^
  File "/home/udhbhav/miniconda3/lib/python3.11/site-packages/airflow/models/taskinstance.py", line 3185, in _execute_task
    return _execute_task(self, context, task_orig)
           ^^^^^^^^^^^^^^^^^^^^^^^^^^^^^^^^^^^^^^^
  File "/home/udhbhav/miniconda3/lib/python3.11/site-packages/airflow/models/taskinstance.py", line 768, in _execute_task
    result = _execute_callable(context=context, **execute_callable_kwargs)
             ^^^^^^^^^^^^^^^^^^^^^^^^^^^^^^^^^^^^^^^^^^^^^^^^^^^^^^^^^^^^^
  File "/home/udhbhav/miniconda3/lib/python3.11/site-packages/airflow/models/taskinstance.py", line 734, in _execute_callable
    return ExecutionCallableRunner(
           ^^^^^^^^^^^^^^^^^^^^^^^^
  File "/home/udhbhav/miniconda3/lib/python3.11/site-packages/airflow/utils/operator_helpers.py", line 252, in run
    return self.func(*args, **kwargs)
           ^^^^^^^^^^^^^^^^^^^^^^^^^^
  File "/home/udhbhav/miniconda3/lib/python3.11/site-packages/airflow/models/baseoperator.py", line 424, in wrapper
    return func(self, *args, **kwargs)
           ^^^^^^^^^^^^^^^^^^^^^^^^^^^
  File "/home/udhbhav/miniconda3/lib/python3.11/site-packages/airflow/operators/python.py", line 901, in execute
    return self.do_branch(context, super().execute(context))
                                   ^^^^^^^^^^^^^^^^^^^^^^^^
  File "/home/udhbhav/miniconda3/lib/python3.11/site-packages/airflow/models/baseoperator.py", line 424, in wrapper
    return func(self, *args, **kwargs)
           ^^^^^^^^^^^^^^^^^^^^^^^^^^^
  File "/home/udhbhav/miniconda3/lib/python3.11/site-packages/airflow/operators/python.py", line 505, in execute
    return super().execute(context=serializable_context)
           ^^^^^^^^^^^^^^^^^^^^^^^^^^^^^^^^^^^^^^^^^^^^^
  File "/home/udhbhav/miniconda3/lib/python3.11/site-packages/airflow/models/baseoperator.py", line 424, in wrapper
    return func(self, *args, **kwargs)
           ^^^^^^^^^^^^^^^^^^^^^^^^^^^
  File "/home/udhbhav/miniconda3/lib/python3.11/site-packages/airflow/operators/python.py", line 238, in execute
    return_value = self.execute_callable()
                   ^^^^^^^^^^^^^^^^^^^^^^^
  File "/home/udhbhav/miniconda3/lib/python3.11/site-packages/airflow/operators/python.py", line 862, in execute_callable
    venv_path = self._ensure_venv_cache_exists(Path(self.venv_cache_path))
                ^^^^^^^^^^^^^^^^^^^^^^^^^^^^^^^^^^^^^^^^^^^^^^^^^^^^^^^^^^
  File "/home/udhbhav/miniconda3/lib/python3.11/site-packages/airflow/operators/python.py", line 856, in _ensure_venv_cache_exists
    raise AirflowException(f"Unable to create new virtual environment in {venv_path}") from e
airflow.exceptions.AirflowException: Unable to create new virtual environment in /tmp/venv-5ea997a7
[2025-03-27T14:43:29.663-0500] {local_task_job_runner.py:266} INFO - Task exited with return code 1
[2025-03-27T14:43:29.802-0500] {taskinstance.py:3901} INFO - 0 downstream tasks scheduled from follow-on schedule check
[2025-03-27T14:43:29.935-0500] {local_task_job_runner.py:245} INFO - ::endgroup::
